Workbook

Sheet НА ПАРСИНГ
A1: Название модели | B1: Обозначение | C1: Наименование | D1: Деталь / Сборка | E1: Пр-во / Закуп | F1: Разраб. | G1: Дата проверки 1 | H1: Пров. | I1: Дата проверки 2 | J1: Т. контр | K1: Дата проверки 3 | L1: Нач. отд. | M1: Дата проверки 4 | N1: Н. контр. | O1: Дата проверки 5 | P1: Утв. | Q1: Дата проверки 6 | R1: Компания
A3: =(IF((E3 = "Пр-во"), (B3 & " - " & C3), C3)) & IF(D3="Сборка", ".iam", ".ipt") -> GG.WP.322.C.0001.0001СБ - Инлет настенный.iam | B3: ='КВ 1'!$B$4 -> GG.WP.322.C.0001.0001СБ | C3: ='КВ 1'!$C$4 -> Инлет настенный | D3: Сборка | E3: Пр-во | F3: Сюткин | G3: 46083 | H3: Макаревич | I3: 46083 | J3: - | K3: - | L3: Макаревич | M3: 46083 | N3: Макаревич | O3: 46083 | P3: Макаревич | Q3: 46083 | R3: ООО "МОЯ ОБОРОНА"
A5: =(IF((E5 = "Пр-во"), (B5 & " - " & C5), C5)) & IF(D5="Сборка", ".iam", ".ipt") -> GG.WP.322.0001.0001СБ - Секция загрузочная GG.WP.322450-S2-L1230-AISI304-TC-СB-A.iam | B5: =' КВ 2'!$B$4 -> GG.WP.322.0001.0001СБ | C5: =' КВ 2'!$C$4 -> Секция загрузочная GG.WP.322450-S2-L1230-AISI304-TC-СB-A | D5: Сборка | E5: Пр-во | F5: Сюткин | G5: 46083 | H5: Макаревич | I5: 46083 | J5: - | K5: - | L5: Макаревич | M5: 46083 | N5: Макаревич | O5: 46083 | P5: Макаревич | Q5: 46083 | R5: ООО "МОЯ ОБОРОНА"
A6: =(IF((E6 = "Пр-во"), (B6 & " - " & C6), C6)) & IF(D6="Сборка", ".iam", ".ipt") -> GG.WP.322.C.0001.0010СБ - Обечайка подвижная.iam | B6: ='КВ 1'!$B$5 -> GG.WP.322.C.0001.0010СБ | C6: ='КВ 1'!$C$5 -> Обечайка подвижная | D6: Сборка | E6: Пр-во | F6: Сюткин | G6: 46083 | H6: Макаревич | I6: 46083 | J6: - | K6: - | L6: Макаревич | M6: 46083 | N6: Макаревич | O6: 46083 | P6: Макаревич | Q6: 46083 | R6: ООО "МОЯ ОБОРОНА"
A7: =(IF((E7 = "Пр-во"), (B7 & " - " & C7), C7)) & IF(D7="Сборка", ".iam", ".ipt") -> GG.WP.322.C.0001.0020СБ - Рамка в сборе.iam | B7: ='КВ 1'!$B$13 -> GG.WP.322.C.0001.0020СБ | C7: ='КВ 1'!$C$13 -> Рамка в сборе | D7: Сборка | E7: Пр-во | F7: Сюткин | G7: 46083 | H7: Макаревич | I7: 46083 | J7: - | K7: - | L7: Макаревич | M7: 46083 | N7: Макаревич | O7: 46083 | P7: Макаревич | Q7: 46083 | R7: ООО "МОЯ ОБОРОНА"
A8: =(IF((E8 = "Пр-во"), (B8 & " - " & C8), C8)) & IF(D8="Сборка", ".iam", ".ipt") -> GG.WP.322.C.0001.0060СБ - Дверца в сборе.iam | B8: ='КВ 1'!$B$31 -> GG.WP.322.C.0001.0060СБ | C8: ='КВ 1'!$C$31 -> Дверца в сборе | D8: Сборка | E8: Пр-во | F8: Сюткин | G8: 46083 | H8: Макаревич | I8: 46083 | J8: - | K8: - | L8: Макаревич | M8: 46083 | N8: Макаревич | O8: 46083 | P8: Макаревич | Q8: 46083 | R8: ООО "МОЯ ОБОРОНА"
A9: =(IF((E9 = "Пр-во"), (B9 & " - " & C9), C9)) & IF(D9="Сборка", ".iam", ".ipt") -> GG.WP.322.C.0001.0080СБ - Замок в сборе.iam | B9: ='КВ 1'!$B$49 -> GG.WP.322.C.0001.0080СБ | C9: ='КВ 1'!$C$49 -> Замок в сборе | D9: Сборка | E9: Пр-во | F9: Сюткин | G9: 46083 | H9: Макаревич | I9: 46083 | J9: - | K9: - | L9: Макаревич | M9: 46083 | N9: Макаревич | O9: 46083 | P9: Макаревич | Q9: 46083 | R9: ООО "МОЯ ОБОРОНА"
A10: =(IF((E10 = "Пр-во"), (B10 & " - " & C10), C10)) & IF(D10="Сборка", ".iam", ".ipt") -> GG.WP.322.C.0001.0090СБ - Приёмный кронштейн в сборе.iam | B10: ='КВ 1'!$B$54 -> GG.WP.322.C.0001.0090СБ | C10: ='КВ 1'!$C$54 -> Приёмный кронштейн в сборе | D10: Сборка | E10: Пр-во | F10: Сюткин | G10: 46083 | H10: Макаревич | I10: 46083 | J10: - | K10: - | L10: Макаревич | M10: 46083 | N10: Макаревич | O10: 46083 | P10: Макаревич | Q10: 46083 | R10: ООО "МОЯ ОБОРОНА"
A11: =(IF((E11 = "Пр-во"), (B11 & " - " & C11), C11)) & IF(D11="Сборка", ".iam", ".ipt") -> GG.WP.322.C.0001.0100СБ - Ответный кронштейн и короб в сборе.iam | B11: ='КВ 1'!$B$59 -> GG.WP.322.C.0001.0100СБ | C11: ='КВ 1'!$C$59 -> Ответный кронштейн и короб в сборе | D11: Сборка | E11: Пр-во | F11: Сюткин | G11: 46083 | H11: Макаревич | I11: 46083 | J11: - | K11: - | L11: Макаревич | M11: 46083 | N11: Макаревич | O11: 46083 | P11: Макаревич | Q11: 46083 | R11: ООО "МОЯ ОБОРОНА"
A13: =(IF((E13 = "Пр-во"), (B13 & " - " & C13), C13)) & IF(D13="Сборка", ".iam", ".ipt") -> GG.WP.322.C.0001.0111 - Планка кронштейна.ipt | B13: ='КВ 1'!$B64 -> GG.WP.322.C.0001.0111 | C13: ='КВ 1'!$C64 -> Планка кронштейна | D13: Деталь | E13: Пр-во | F13: Сюткин | G13: 46083 | H13: Макаревич | I13: 46083 | J13: - | K13: - | L13: Макаревич | M13: 46083 | N13: Макаревич | O13: 46083 | P13: Макаревич | Q13: 46083 | R13: ООО "МОЯ ОБОРОНА"
A14: =(IF((E14 = "Пр-во"), (B14 & " - " & C14), C14)) & IF(D14="Сборка", ".iam", ".ipt") -> GG.WP.322.C.0001.0112 - Прокладка.ipt | B14: ='КВ 1'!$B65 -> GG.WP.322.C.0001.0112 | C14: ='КВ 1'!$C65 -> Прокладка | D14: Деталь | E14: Пр-во | F14: Сюткин | G14: 46083 | H14: Макаревич | I14: 46083 | J14: - | K14: - | L14: Макаревич | M14: 46083 | N14: Макаревич | O14: 46083 | P14: Макаревич | Q14: 46083 | R14: ООО "МОЯ ОБОРОНА"
A15: =(IF((E15 = "Пр-во"), (B15 & " - " & C15), C15)) & IF(D15="Сборка", ".iam", ".ipt") -> GG.WP.322.C.0001.0113 - S 9216K уплотнитель вертикальный.ipt | B15: ='КВ 1'!$B66 -> GG.WP.322.C.0001.0113 | C15: ='КВ 1'!$C66 -> S 9216K уплотнитель вертикальный | D15: Деталь | E15: Пр-во | F15: Сюткин | G15: 46083 | H15: Макаревич | I15: 46083 | J15: - | K15: - | L15: Макаревич | M15: 46083 | N15: Макаревич | O15: 46083 | P15: Макаревич | Q15: 46083 | R15: ООО "МОЯ ОБОРОНА"
A16: =(IF((E16 = "Пр-во"), (B16 & " - " & C16), C16)) & IF(D16="Сборка", ".iam", ".ipt") -> GG.WP.322.C.0001.0114 - S 9216K уплотнитель горизонтальный.ipt | B16: ='КВ 1'!$B67 -> GG.WP.322.C.0001.0114 | C16: ='КВ 1'!$C67 -> S 9216K уплотнитель горизонтальный | D16: Деталь | E16: Пр-во | F16: Сюткин | G16: 46083 | H16: Макаревич | I16: 46083 | J16: - | K16: - | L16: Макаревич | M16: 46083 | N16: Макаревич | O16: 46083 | P16: Макаревич | Q16: 46083 | R16: ООО "МОЯ ОБОРОНА"
A17: =(IF((E17 = "Пр-во"), (B17 & " - " & C17), C17)) & IF(D17="Сборка", ".iam", ".ipt") -> Втулка дверцы.ipt | B17: ='КВ 1'!$B68 -> - | C17: ='КВ 1'!$C68 -> Втулка дверцы | D17: Деталь | E17: Закуп | F17: Сюткин | G17: 46083 | H17: Макаревич | I17: 46083 | J17: - | K17: - | L17: Макаревич | M17: 46083 | N17: Макаревич | O17: 46083 | P17: Макаревич | Q17: 46083 | R17: ООО "МОЯ ОБОРОНА"
A19: =(IF((E19 = "Пр-во"), (B19 & " - " & C19), C19)) & IF(D19="Сборка", ".iam", ".ipt") -> Гайка DIN 934 M6x1.0 ZN.ipt | B19: ='КВ 1'!$B69 -> - | C19: ='КВ 1'!$C69 -> Гайка DIN 934 M6x1.0 ZN | D19: Деталь | E19: Закуп | F19: - | G19: - | H19: - | I19: - | J19: - | K19: - | L19: - | M19: - | N19: - | O19: - | P19: - | Q19: - | R19: -
A20: =(IF((E20 = "Пр-во"), (B20 & " - " & C20), C20)) & IF(D20="Сборка", ".iam", ".ipt") -> Гайка ТЕХНОТРОН ГсРФ M6x1.ipt | B20: ='КВ 1'!$B70 -> - | C20: ='КВ 1'!$C70 -> Гайка ТЕХНОТРОН ГсРФ M6x1 | D20: Деталь | E20: Закуп | F20: - | G20: - | H20: - | I20: - | J20: - | K20: - | L20: - | M20: - | N20: - | O20: - | P20: - | Q20: - | R20: -
A21: =(IF((E21 = "Пр-во"), (B21 & " - " & C21), C21)) & IF(D21="Сборка", ".iam", ".ipt") -> Винт DIN 965 M5x16x0.8 A2.ipt | B21: ='КВ 1'!$B71 -> - | C21: ='КВ 1'!$C71 -> Винт DIN 965 M5x16x0.8 A2 | D21: Деталь | E21: Закуп | F21: - | G21: - | H21: - | I21: - | J21: - | K21: - | L21: - | M21: - | N21: - | O21: - | P21: - | Q21: - | R21: -
A22: =(IF((E22 = "Пр-во"), (B22 & " - " & C22), C22)) & IF(D22="Сборка", ".iam", ".ipt") -> Винт DIN 965 M5x80x0.8 A2.ipt | B22: ='КВ 1'!$B72 -> - | C22: ='КВ 1'!$C72 -> Винт DIN 965 M5x80x0.8 A2 | D22: Деталь | E22: Закуп | F22: - | G22: - | H22: - | I22: - | J22: - | K22: - | L22: - | M22: - | N22: - | O22: - | P22: - | Q22: - | R22: -
A24: =(IF((E24 = "Пр-во"), (B24 & " - " & C24), C24)) & IF(D24="Сборка", ".iam", ".ipt") -> GG.WP.322.0001.0010СБ - Обечайка в сборе.iam | B24: =' КВ 2'!$B$5 -> GG.WP.322.0001.0010СБ | C24: =' КВ 2'!$C$5 -> Обечайка в сборе | D24: Сборка | E24: Пр-во | F24: Сюткин | G24: 46083 | H24: Макаревич | I24: 46083 | J24: - | K24: - | L24: Макаревич | M24: 46083 | N24: Макаревич | O24: 46083 | P24: Макаревич | Q24: 46083 | R24: ООО "МОЯ ОБОРОНА"
A26: =(IF((E26 = "Пр-во"), (B26 & " - " & C26), C26)) & IF(D26="Сборка", ".iam", ".ipt") -> GG.WP.322.0001.0031 - Секция.ipt | B26: =' КВ 2'!$B$15 -> GG.WP.322.0001.0031 | C26: =' КВ 2'!$C$15 -> Секция | D26: Деталь | E26: Пр-во | F26: Сюткин | G26: 46083 | H26: Макаревич | I26: 46083 | J26: - | K26: - | L26: Макаревич | M26: 46083 | N26: Макаревич | O26: 46083 | P26: Макаревич | Q26: 46083 | R26: ООО "МОЯ ОБОРОНА"
A28: =(IF((E28 = "Пр-во"), (B28 & " - " & C28), C28)) & IF(D28="Сборка", ".iam", ".ipt") -> GG.WP.322.0001.0022 - Лист нижний.ipt | B28: =' КВ 2'!$B6 -> GG.WP.322.0001.0022 | C28: =' КВ 2'!$C6 -> Лист нижний | D28: Деталь | E28: Пр-во | F28: Сюткин | G28: 46083 | H28: Макаревич | I28: 46083 | J28: - | K28: - | L28: Макаревич | M28: 46083 | N28: Макаревич | O28: 46083 | P28: Макаревич | Q28: 46083 | R28: ООО "МОЯ ОБОРОНА"
A29: =(IF((E29 = "Пр-во"), (B29 & " - " & C29), C29)) & IF(D29="Сборка", ".iam", ".ipt") -> GG.WP.322.0001.0023 - Упор.ipt | B29: =' КВ 2'!$B7 -> GG.WP.322.0001.0023 | C29: =' КВ 2'!$C7 -> Упор | D29: Деталь | E29: Пр-во | F29: Сюткин | G29: 46083 | H29: Макаревич | I29: 46083 | J29: - | K29: - | L29: Макаревич | M29: 46083 | N29: Макаревич | O29: 46083 | P29: Макаревич | Q29: 46083 | R29: ООО "МОЯ ОБОРОНА"
A30: =(IF((E30 = "Пр-во"), (B30 & " - " & C30), C30)) & IF(D30="Сборка", ".iam", ".ipt") -> GG.WP.322.0001.0024 - Лист боковой правый.ipt | B30: =' КВ 2'!$B8 -> GG.WP.322.0001.0024 | C30: =' КВ 2'!$C8 -> Лист боковой правый | D30: Деталь | E30: Пр-во | F30: Сюткин | G30: 46083 | H30: Макаревич | I30: 46083 | J30: - | K30: - | L30: Макаревич | M30: 46083 | N30: Макаревич | O30: 46083 | P30: Макаревич | Q30: 46083 | R30: ООО "МОЯ ОБОРОНА"
A31: =(IF((E31 = "Пр-во"), (B31 & " - " & C31), C31)) & IF(D31="Сборка", ".iam", ".ipt") -> GG.WP.322.0001.0025 - Лист боковой левый.ipt | B31: =' КВ 2'!$B9 -> GG.WP.322.0001.0025 | C31: =' КВ 2'!$C9 -> Лист боковой левый | D31: Деталь | E31: Пр-во | F31: Сюткин | G31: 46083 | H31: Макаревич | I31: 46083 | J31: - | K31: - | L31: Макаревич | M31: 46083 | N31: Макаревич | O31: 46083 | P31: Макаревич | Q31: 46083 | R31: ООО "МОЯ ОБОРОНА"
A32: =(IF((E32 = "Пр-во"), (B32 & " - " & C32), C32)) & IF(D32="Сборка", ".iam", ".ipt") -> GG.WP.322.0001.0026 - Лист верхний.ipt | B32: =' КВ 2'!$B10 -> GG.WP.322.0001.0026 | C32: =' КВ 2'!$C10 -> Лист верхний | D32: Деталь | E32: Пр-во | F32: Сюткин | G32: 46083 | H32: Макаревич | I32: 46083 | J32: - | K32: - | L32: Макаревич | M32: 46083 | N32: Макаревич | O32: 46083 | P32: Макаревич | Q32: 46083 | R32: ООО "МОЯ ОБОРОНА"
A33: =(IF((E33 = "Пр-во"), (B33 & " - " & C33), C33)) & IF(D33="Сборка", ".iam", ".ipt") -> GG.WP.322.0001.0028 - Уголок правый.ipt | B33: =' КВ 2'!$B11 -> GG.WP.322.0001.0028 | C33: =' КВ 2'!$C11 -> Уголок правый | D33: Деталь | E33: Пр-во | F33: Сюткин | G33: 46083 | H33: Макаревич | I33: 46083 | J33: - | K33: - | L33: Макаревич | M33: 46083 | N33: Макаревич | O33: 46083 | P33: Макаревич | Q33: 46083 | R33: ООО "МОЯ ОБОРОНА"
A34: =(IF((E34 = "Пр-во"), (B34 & " - " & C34), C34)) & IF(D34="Сборка", ".iam", ".ipt") -> GG.WP.322.0001.0029 - Уголок левый.ipt | B34: =' КВ 2'!$B12 -> GG.WP.322.0001.0029 | C34: =' КВ 2'!$C12 -> Уголок левый | D34: Деталь | E34: Пр-во | F34: Сюткин | G34: 46083 | H34: Макаревич | I34: 46083 | J34: - | K34: - | L34: Макаревич | M34: 46083 | N34: Макаревич | O34: 46083 | P34: Макаревич | Q34: 46083 | R34: ООО "МОЯ ОБОРОНА"
A36: =(IF((E36 = "Пр-во"), (B36 & " - " & C36), C36)) & IF(D36="Сборка", ".iam", ".ipt") -> Гайка для контактной сварки DIN 929-M5-A2.ipt | B36: =' КВ 2'!$B13 -> - | C36: =' КВ 2'!$C13 -> Гайка для контактной сварки DIN 929-M5-A2 | D36: Деталь | E36: Закуп | F36: - | G36: - | H36: - | I36: - | J36: - | K36: - | L36: - | M36: - | N36: - | O36: - | P36: - | Q36: - | R36: -
A37: =(IF((E37 = "Пр-во"), (B37 & " - " & C37), C37)) & IF(D37="Сборка", ".iam", ".ipt") -> Шпилька DIN976-1-M6x40-B-8.8-A2.ipt | B37: =' КВ 2'!$B14 -> - | C37: =' КВ 2'!$C14 -> Шпилька DIN976-1-M6x40-B-8.8-A2 | D37: Деталь | E37: Закуп | F37: - | G37: - | H37: - | I37: - | J37: - | K37: - | L37: - | M37: - | N37: - | O37: - | P37: - | Q37: - | R37: -
A39: =(IF((E39 = "Пр-во"), (B39 & " - " & C39), C39)) & IF(D39="Сборка", ".iam", ".ipt") -> GG.WP.322.C.0001.0011 - Лист нижний.ipt | B39: ='КВ 1'!$B6 -> GG.WP.322.C.0001.0011 | C39: ='КВ 1'!$C6 -> Лист нижний | D39: Деталь | E39: Пр-во | F39: Сюткин | G39: 46083 | H39: Макаревич | I39: 46083 | J39: - | K39: - | L39: Макаревич | M39: 46083 | N39: Макаревич | O39: 46083 | P39: Макаревич | Q39: 46083 | R39: ООО "МОЯ ОБОРОНА"
A40: =(IF((E40 = "Пр-во"), (B40 & " - " & C40), C40)) & IF(D40="Сборка", ".iam", ".ipt") -> GG.WP.322.C.0001.0012 - Лист верхний.ipt | B40: ='КВ 1'!$B7 -> GG.WP.322.C.0001.0012 | C40: ='КВ 1'!$C7 -> Лист верхний | D40: Деталь | E40: Пр-во | F40: Сюткин | G40: 46083 | H40: Макаревич | I40: 46083 | J40: - | K40: - | L40: Макаревич | M40: 46083 | N40: Макаревич | O40: 46083 | P40: Макаревич | Q40: 46083 | R40: ООО "МОЯ ОБОРОНА"
A41: =(IF((E41 = "Пр-во"), (B41 & " - " & C41), C41)) & IF(D41="Сборка", ".iam", ".ipt") -> GG.WP.322.C.0001.0013 - Лист правый.ipt | B41: ='КВ 1'!$B8 -> GG.WP.322.C.0001.0013 | C41: ='КВ 1'!$C8 -> Лист правый | D41: Деталь | E41: Пр-во | F41: Сюткин | G41: 46083 | H41: Макаревич | I41: 46083 | J41: - | K41: - | L41: Макаревич | M41: 46083 | N41: Макаревич | O41: 46083 | P41: Макаревич | Q41: 46083 | R41: ООО "МОЯ ОБОРОНА"
A42: =(IF((E42 = "Пр-во"), (B42 & " - " & C42), C42)) & IF(D42="Сборка", ".iam", ".ipt") -> GG.WP.322.C.0001.0014 - Лист левый.ipt | B42: ='КВ 1'!$B9 -> GG.WP.322.C.0001.0014 | C42: ='КВ 1'!$C9 -> Лист левый | D42: Деталь | E42: Пр-во | F42: Сюткин | G42: 46083 | H42: Макаревич | I42: 46083 | J42: - | K42: - | L42: Макаревич | M42: 46083 | N42: Макаревич | O42: 46083 | P42: Макаревич | Q42: 46083 | R42: ООО "МОЯ ОБОРОНА"
A43: =(IF((E43 = "Пр-во"), (B43 & " - " & C43), C43)) & IF(D43="Сборка", ".iam", ".ipt") -> GG.WP.322.C.0001.0015 - Салазки.ipt | B43: ='КВ 1'!$B10 -> GG.WP.322.C.0001.0015 | C43: ='КВ 1'!$C10 -> Салазки | D43: Деталь | E43: Пр-во | F43: Сюткин | G43: 46083 | H43: Макаревич | I43: 46083 | J43: - | K43: - | L43: Макаревич | M43: 46083 | N43: Макаревич | O43: 46083 | P43: Макаревич | Q43: 46083 | R43: ООО "МОЯ ОБОРОНА"
A44: =(IF((E44 = "Пр-во"), (B44 & " - " & C44), C44)) & IF(D44="Сборка", ".iam", ".ipt") -> GG.WP.322.C.0001.0016 - Втулка направляющая.ipt | B44: ='КВ 1'!$B11 -> GG.WP.322.C.0001.0016 | C44: ='КВ 1'!$C11 -> Втулка направляющая | D44: Деталь | E44: Пр-во | F44: Сюткин | G44: 46083 | H44: Макаревич | I44: 46083 | J44: - | K44: - | L44: Макаревич | M44: 46083 | N44: Макаревич | O44: 46083 | P44: Макаревич | Q44: 46083 | R44: ООО "МОЯ ОБОРОНА"
A46: =(IF((E46 = "Пр-во"), (B46 & " - " & C46), C46)) & IF(D46="Сборка", ".iam", ".ipt") -> Гайка-заклепка М5x13x0.8 A2.ipt | B46: ='КВ 1'!$B12 -> - | C46: ='КВ 1'!$C12 -> Гайка-заклепка М5x13x0.8 A2 | D46: Деталь | E46: Закуп | F46: - | G46: - | H46: - | I46: - | J46: - | K46: - | L46: - | M46: - | N46: - | O46: - | P46: - | Q46: - | R46: -
A48: =(IF((E48 = "Пр-во"), (B48 & " - " & C48), C48)) & IF(D48="Сборка", ".iam", ".ipt") -> GG.WP.322.C.0001.0021СБ - Рамка.iam | B48: ='КВ 1'!$B14 -> GG.WP.322.C.0001.0021СБ | C48: ='КВ 1'!$C14 -> Рамка | D48: Сборка | E48: Пр-во | F48: Сюткин | G48: 46083 | H48: Макаревич | I48: 46083 | J48: - | K48: - | L48: Макаревич | M48: 46083 | N48: Макаревич | O48: 46083 | P48: Макаревич | Q48: 46083 | R48: ООО "МОЯ ОБОРОНА"
A49: =(IF((E49 = "Пр-во"), (B49 & " - " & C49), C49)) & IF(D49="Сборка", ".iam", ".ipt") -> GG.WP.322.C.0001.0030СБ - Корпус сенсора в сборе.iam | B49: ='КВ 1'!$B$21 -> GG.WP.322.C.0001.0030СБ | C49: ='КВ 1'!$C$21 -> Корпус сенсора в сборе | D49: Сборка | E49: Пр-во | F49: Сюткин | G49: 46083 | H49: Макаревич | I49: 46083 | J49: - | K49: - | L49: Макаревич | M49: 46083 | N49: Макаревич | O49: 46083 | P49: Макаревич | Q49: 46083 | R49: ООО "МОЯ ОБОРОНА"
A50: =(IF((E50 = "Пр-во"), (B50 & " - " & C50), C50)) & IF(D50="Сборка", ".iam", ".ipt") -> GG.WP.322.C.0001.0040СБ - Короб динамика в сборе.iam | B50: ='КВ 1'!$B$22 -> GG.WP.322.C.0001.0040СБ | C50: ='КВ 1'!$C$22 -> Короб динамика в сборе | D50: Сборка | E50: Пр-во | F50: Сюткин | G50: 46083 | H50: Макаревич | I50: 46083 | J50: - | K50: - | L50: Макаревич | M50: 46083 | N50: Макаревич | O50: 46083 | P50: Макаревич | Q50: 46083 | R50: ООО "МОЯ ОБОРОНА"
A52: =(IF((E52 = "Пр-во"), (B52 & " - " & C52), C52)) & IF(D52="Сборка", ".iam", ".ipt") -> GG.WP.322.C.0001.0050 - Стопор дверцы.ipt | B52: ='КВ 1'!B26 -> GG.WP.322.C.0001.0050 | C52: ='КВ 1'!C26 -> Стопор дверцы | D52: Деталь | E52: Пр-во | F52: Сюткин | G52: 46083 | H52: Макаревич | I52: 46083 | J52: - | K52: - | L52: Макаревич | M52: 46083 | N52: Макаревич | O52: 46083 | P52: Макаревич | Q52: 46083 | R52: ООО "МОЯ ОБОРОНА"
...

Sheet КВ 1
E1: 1
B2: Состав изделия | C2: Наименование и артикул изделия | D2: Инлет GG.WP.322.C | F2: Листов 1
A3: № п/п | B3: Обозначение | C3: Наименование | D3: Кол-во на 1 комплект | E3: Кол-во на заказ | F3: Примечание | G3: Производитель | H3: Комменатрии | I3: Ссылки и материалы | K3: Визуальные метки | M3: Шифр меток
B4: GG.WP.322.C.0001.0001СБ | C4: Инлет настенный | D4: 1 | F4: Сборочная единица | G4: Делатель раз | M4: Сборка
B5: GG.WP.322.C.0001.0010СБ | C5: Обечайка подвижная | D5: 1 | F5: Сборочная единица | G5: Делатель раз | M5: Уехавшие детали от сборки
B6: GG.WP.322.C.0001.0011 | C6: Лист нижний | D6: 1 | F6: Детали | G6: Делатель раз
B7: GG.WP.322.C.0001.0012 | C7: Лист верхний | D7: 1 | F7: Детали | G7: Делатель раз
B8: GG.WP.322.C.0001.0013 | C8: Лист правый | D8: 1 | F8: Детали | G8: Делатель раз
B9: GG.WP.322.C.0001.0014 | C9: Лист левый | D9: 1 | F9: Детали | G9: Делатель раз
B10: GG.WP.322.C.0001.0015 | C10: Салазки | D10: 4 | F10: Детали | G10: Делатель раз
B11: GG.WP.322.C.0001.0016 | C11: Втулка направляющая | D11: 4 | F11: Детали | G11: Делатель раз
B12: - | C12: Гайка-заклепка М5x13x0.8 A2 | D12: 9 | F12: Детали (покупное изделие) | G12: Делатель раз
B13: GG.WP.322.C.0001.0020СБ | C13: Рамка в сборе | D13: 1 | F13: Сборочная единица | G13: Делатель раз
B14: GG.WP.322.C.0001.0021СБ | C14: Рамка | D14: 1 | F14: Сборочная единица | G14: Делатель раз
B15: GG.WP.322.C.0001.0022 | C15: Короб | D15: 1 | F15: Детали | G15: Делатель раз
B16: GG.WP.322.C.0001.0023 | C16: Пластина фронтальная | D16: 1 | F16: Детали | G16: Делатель раз
B17: - | C17: Шпилька приварная M5x15x0.8 A2 | D17: 4 | F17: Детали (покупное изделие) | G17: Делатель раз
... B72: - | C72: Винт DIN 965 M5x80x0.8 A2 | D72: 4 | F72: Детали (покупное изделие) | G72: Делатель раз
D73: Фамилия | F73: Дата, тел.
C74: Разработал | D74: Ивлев | F74: 46126
C75: Проверил
A76: Изм. | B76: № документа

Sheet  КВ 2
E1: 1
B2: Состав изделия | C2: Наименование и артикул изделия | D2: Инлет EP.350.400.C | F2: Листов 1
A3: № п/п | B3: Обозначение | C3: Наименование | D3: Кол-во на 1 комплект | E3: Кол-во на заказ | F3: Примечание | G3: Производитель | H3: Комменатрии | I3: Ссылки и материалы | K3: Визуальные метки | M3: Шифр меток
B4: GG.WP.322.0001.0001СБ | C4: Секция загрузочная GG.WP.322450-S2-L1230-AISI304-TC-СB-A | D4: 1 | F4: Сборочная единица | G4: Делатель 3 | M4: Сборка
B5: GG.WP.322.0001.0010СБ | C5: Обечайка в сборе | D5: 1 | F5: Сборочная единица | G5: Делатель 3 | M5: Уехавшие детали от сборки
B6: GG.WP.322.0001.0022 | C6: Лист нижний | D6: 1 | F6: Детали | G6: Делатель 3
B7: GG.WP.322.0001.0023 | C7: Упор | D7: 4 | F7: Детали | G7: Делатель 3
B8: GG.WP.322.0001.0024 | C8: Лист боковой правый | D8: 1 | F8: Детали | G8: Делатель 3
B9: GG.WP.322.0001.0025 | C9: Лист боковой левый | D9: 1 | F9: Детали | G9: Делатель 3
B10: GG.WP.322.0001.0026 | C10: Лист верхний | D10: 1 | F10: Детали | G10: Делатель 3
B11: GG.WP.322.0001.0028 | C11: Уголок правый | D11: 2 | F11: Детали | G11: Делатель 3
B12: GG.WP.322.0001.0029 | C12: Уголок левый | D12: 2 | F12: Детали | G12: Делатель 3
B13: - | C13: Гайка для контактной сварки DIN 929-M5-A2 | D13: 4 | F13: Детали (покупное изделие) | G13: Делатель 3
B14: - | C14: Шпилька DIN976-1-M6x40-B-8.8-A2 | D14: 4 | F14: Детали (покупное изделие) | G14: Делатель 3
B15: GG.WP.322.0001.0031 | C15: Секция | D15: 1 | F15: Детали | G15: Делатель 3
D16: Фамилия | F16: Дата, тел.
C17: Разработал | D17: Ивлев | F17: 46126
C18: Проверил
A19: Изм. | B19: № документа

Sheet ПИ 1
E1: 1
B2: Состав изделия | C2: Наименвоание и артикул изделия | D2: Секция инспекционная PZR-VTP-IS-LIS-350-S2-L1240-F2-RAL6029 | F2: Листов 1
A3: № п/п | B3: Обозначение | C3: Наименование | D3: Кол-во на 1 комплект | E3: Кол-во на заказ | F3: Примечание | G3: Производитель | H3: Комменатрии | I3: Ссылки и материалы
B4: ='КВ 1'!B12 -> - | C4: ='КВ 1'!C12 -> Гайка-заклепка М5x13x0.8 A2 | D4: ='КВ 1'!D12 -> 9 | E4: ='КВ 1'!E12 -> 0 | F4: ='КВ 1'!F12 -> Детали (покупное изделие) | G4: ='КВ 1'!G12 -> Делатель раз | H4: ='КВ 1'!H12 -> 0 | I4: ='КВ 1'!I12 -> 0
B5: ='КВ 1'!B17 -> - | C5: ='КВ 1'!C17 -> Шпилька приварная M5x15x0.8 A2 | D5: ='КВ 1'!D17 -> 4 | E5: ='КВ 1'!E17 -> 0 | F5: ='КВ 1'!F17 -> Детали (покупное изделие) | G5: ='КВ 1'!G17 -> Делатель раз | H5: ='КВ 1'!H17 -> 0 | I5: ='КВ 1'!I17 -> 0
B6: ='КВ 1'!B18 -> - | C6: ='КВ 1'!C18 -> Шайба DIN 125 M5 A2 | D6: ='КВ 1'!D18 -> 2 | E6: ='КВ 1'!E18 -> 0 | F6: ='КВ 1'!F18 -> Детали (покупное изделие) | G6: ='КВ 1'!G18 -> Делатель раз | H6: ='КВ 1'!H18 -> 0 | I6: ='КВ 1'!I18 -> 0
B7: ='КВ 1'!B19 -> - | C7: ='КВ 1'!C19 -> Шайба-гровер DIN 127 M5 A2 | D7: ='КВ 1'!D19 -> 2 | E7: ='КВ 1'!E19 -> 0 | F7: ='КВ 1'!F19 -> Детали (покупное изделие) | G7: ='КВ 1'!G19 -> Делатель раз | H7: ='КВ 1'!H19 -> 0 | I7: ='КВ 1'!I19 -> 0
B8: ='КВ 1'!B20 -> - | C8: ='КВ 1'!C20 -> Гайка DIN 934 M5x0.8 A2 | D8: ='КВ 1'!D20 -> 2 | E8: ='КВ 1'!E20 -> 0 | F8: ='КВ 1'!F20 -> Детали (покупное изделие) | G8: ='КВ 1'!G20 -> Делатель раз | H8: ='КВ 1'!H20 -> 0 | I8: ='КВ 1'!I20 -> 0
B9: ='КВ 1'!B23 -> - | C9: ='КВ 1'!C23 -> Динамик | D9: ='КВ 1'!D23 -> 1 | E9: ='КВ 1'!E23 -> 0 | F9: ='КВ 1'!F23 -> Сборочная единица (покупное изделие) | G9: ='КВ 1'!G23 -> Делатель раз | H9: ='КВ 1'!H23 -> 0 | I9: ='КВ 1'!I23 -> 0
B10: ='КВ 1'!B25 -> - | C10: ='КВ 1'!C25 -> Винт DIN 7500 M3x10x0.5 A2 | D10: ='КВ 1'!D25 -> 4 | E10: ='КВ 1'!E25 -> 0 | F10: ='КВ 1'!F25 -> Детали (покупное изделие) | G10: ='КВ 1'!G25 -> Делатель раз | H10: ='КВ 1'!H25 -> 0 | I10: ='КВ 1'!I25 -> 0
B11: ='КВ 1'!B27 -> - | C11: ='КВ 1'!C27 -> Шайба DIN 125 M5 A2 | D11: ='КВ 1'!D27 -> 2 | E11: ='КВ 1'!E27 -> 0 | F11: ='КВ 1'!F27 -> Детали (покупное изделие) | G11: ='КВ 1'!G27 -> Делатель раз | H11: ='КВ 1'!H27 -> 0 | I11: ='КВ 1'!I27 -> 0
B12: ='КВ 1'!B28 -> - | C12: ='КВ 1'!C28 -> Шайба-гровер DIN 127 M5 A2 | D12: ='КВ 1'!D28 -> 2 | E12: ='КВ 1'!E28 -> 0 | F12: ='КВ 1'!F28 -> Детали (покупное изделие) | G12: ='КВ 1'!G28 -> Делатель раз | H12: ='КВ 1'!H28 -> 0 | I12: ='КВ 1'!I28 -> 0
B13: ='КВ 1'!B29 -> - | C13: ='КВ 1'!C29 -> Гайка DIN 934 M5x0.8 A2 | D13: ='КВ 1'!D29 -> 2 | E13: ='КВ 1'!E29 -> 0 | F13: ='КВ 1'!F29 -> Детали (покупное изделие) | G13: ='КВ 1'!G29 -> Делатель раз | H13: ='КВ 1'!H29 -> 0 | I13: ='КВ 1'!I29 -> 0
B14: ='КВ 1'!B30 -> - | C14: ='КВ 1'!C30 -> Винт DIN 7500 M3x10x0.5 A2 | D14: ='КВ 1'!D30 -> 2 | E14: ='КВ 1'!E30 -> 0 | F14: ='КВ 1'!F30 -> Детали (покупное изделие) | G14: ='КВ 1'!G30 -> Делатель раз | H14: ='КВ 1'!H30 -> 0 | I14: ='КВ 1'!I30 -> 0
B15: ='КВ 1'!B34 -> - | C15: ='КВ 1'!C34 -> Приварная гайка DIN 929 M5x0.8 A2 | D15: ='КВ 1'!D34 -> 7 | E15: ='КВ 1'!E34 -> 0 | F15: ='КВ 1'!F34 -> Детали (покупное изделие) | G15: ='КВ 1'!G34 -> Делатель раз | H15: ='КВ 1'!H34 -> 0 | I15: ='КВ 1'!I34 -> 0
B16: ='КВ 1'!B35 -> - | C16: ='КВ 1'!C35 -> Петля | D16: ='КВ 1'!D35 -> 2 | E16: ='КВ 1'!E35 -> 0 | F16: ='КВ 1'!F35 -> Сборочная единица (покупное изделие) | G16: ='КВ 1'!G35 -> Делатель раз | H16: ='КВ 1'!H35 -> 0 | I16: ='КВ 1'!I35 -> 0
B17: ='КВ 1'!B47 -> - | C17: ='КВ 1'!C47 -> Гайка DIN 934 M3x0.5 A2 | D17: ='КВ 1'!D47 -> 4 | E17: ='КВ 1'!E47 -> 0 | F17: ='КВ 1'!F47 -> Детали (покупное изделие) | G17: ='КВ 1'!G47 -> Делатель раз | H17: ='КВ 1'!H47 -> 0 | I17: ='КВ 1'!I47 -> 0
B18: ='КВ 1'!B48 -> - | C18: ='КВ 1'!C48 -> Винт DIN 965 M5x12x0.8 A2 | D18: ='КВ 1'!D48 -> 7 | E18: ='КВ 1'!E48 -> 0 | F18: ='КВ 1'!F48 -> Детали (покупное изделие) | G18: ='КВ 1'!G48 -> Делатель раз | H18: ='КВ 1'!H48 -> 0 | I18: ='КВ 1'!I48 -> 0
B19: ='КВ 1'!B50 -> GG.WP.322.C.0001.0081СБ | C19: ='КВ 1'!C50 -> Замок | D19: ='КВ 1'!D50 -> 1 | E19: ='КВ 1'!E50 -> 0 | F19: ='КВ 1'!F50 -> Сборочная единица (покупное изделие) | G19: ='КВ 1'!G50 -> Делатель два | H19: ='КВ 1'!H50 -> 0 | I19: ='КВ 1'!I50 -> 0
B20: ='КВ 1'!B52 -> - | C20: ='КВ 1'!C52 -> Гайка-заклепка М5x13x0.8 A2 | D20: ='КВ 1'!D52 -> 4 | E20: ='КВ 1'!E52 -> 0 | F20: ='КВ 1'!F52 -> Детали (покупное изделие) | G20: ='КВ 1'!G52 -> Делатель два | H20: ='КВ 1'!H52 -> 0 | I20: ='КВ 1'!I52 -> 0
B21: ='КВ 1'!B53 -> - | C21: ='КВ 1'!C53 -> Винт DIN 912 M4x12x0.7 A2 | D21: ='КВ 1'!D53 -> 4 | E21: ='КВ 1'!E53 -> 0 | F21: ='КВ 1'!F53 -> Детали (покупное изделие) | G21: ='КВ 1'!G53 -> Делатель два | H21: ='КВ 1'!H53 -> 0 | I21: ='КВ 1'!I53 -> 0
B22: ='КВ 1'!B56 -> - | C22: ='КВ 1'!C56 -> Неодимовый магнит (диск) 15х3 с зенковкой 4.5x7.5 | D22: ='КВ 1'!D56 -> 2 | E22: ='КВ 1'!E56 -> 0 | F22: ='КВ 1'!F56 -> Детали (покупное изделие) | G22: ='КВ 1'!G56 -> Делатель два | H22: ='КВ 1'!H56 -> 0 | I22: ='КВ 1'!I56 -> 0
B23: ='КВ 1'!B57 -> - | C23: ='КВ 1'!C57 -> Приварная гайка DIN 929 M4x0.7 ZN | D23: ='КВ 1'!D57 -> 2 | E23: ='КВ 1'!E57 -> 0 | F23: ='КВ 1'!F57 -> Детали (покупное изделие) | G23: ='КВ 1'!G57 -> Делатель два | H23: ='КВ 1'!H57 -> 0 | I23: ='КВ 1'!I57 -> 0
B24: ='КВ 1'!B58 -> - | C24: ='КВ 1'!C58 -> Винт DIN 929 M4x0.7 ZN | D24: ='КВ 1'!D58 -> 2 | E24: ='КВ 1'!E58 -> 0 | F24: ='КВ 1'!F58 -> Детали (покупное изделие) | G24: ='КВ 1'!G58 -> Делатель два | H24: ='КВ 1'!H58 -> 0 | I24: ='КВ 1'!I58 -> 0
B25: ='КВ 1'!B60 -> GG.WP.322.C.0001.0101СБ | C25: ='КВ 1'!C60 -> Короб с электроникой в сборе | D25: ='КВ 1'!D60 -> 1 | E25: ='КВ 1'!E60 -> 0 | F25: ='КВ 1'!F60 -> Сборочная единица (покупное изделие) | G25: ='КВ 1'!G60 -> Делатель два | H25: ='КВ 1'!H60 -> 0 | I25: ='КВ 1'!I60 -> 0
B26: ='КВ 1'!B62 -> - | C26: ='КВ 1'!C62 -> Приварная гайка DIN 929 M6x1 ZN | D26: ='КВ 1'!D62 -> 4 | E26: ='КВ 1'!E62 -> 0 | F26: ='КВ 1'!F62 -> Детали (покупное изделие) | G26: ='КВ 1'!G62 -> Делатель два | H26: ='КВ 1'!H62 -> 0 | I26: ='КВ 1'!I62 -> 0
B27: ='КВ 1'!B63 -> - | C27: ='КВ 1'!C63 -> Винт DIN 7420 M5x16x0.8 A2 | D27: ='КВ 1'!D63 -> 4 | E27: ='КВ 1'!E63 -> 0 | F27: ='КВ 1'!F63 -> Детали (покупное изделие) | G27: ='КВ 1'!G63 -> Делатель два | H27: ='КВ 1'!H63 -> 0 | I27: ='КВ 1'!I63 -> 0
B28: ='КВ 1'!B68 -> - | C28: ='КВ 1'!C68 -> Втулка дверцы | D28: ='КВ 1'!D68 -> 2 | E28: ='КВ 1'!E68 -> 0 | F28: ='КВ 1'!F68 -> Детали (покупное изделие) | G28: ='КВ 1'!G68 -> Делатель раз | H28: ='КВ 1'!H68 -> 0 | I28: ='КВ 1'!I68 -> 0
B29: ='КВ 1'!B69 -> - | C29: ='КВ 1'!C69 -> Гайка DIN 934 M6x1.0 ZN | D29: ='КВ 1'!D69 -> 4 | E29: ='КВ 1'!E69 -> 0 | F29: ='КВ 1'!F69 -> Детали (покупное изделие) | G29: ='КВ 1'!G69 -> Делатель два | H29: ='КВ 1'!H69 -> 0 | I29: ='КВ 1'!I69 -> 0
B30: ='КВ 1'!B70 -> - | C30: ='КВ 1'!C70 -> Гайка ТЕХНОТРОН ГсРФ M6x1 | D30: ='КВ 1'!D70 -> 4 | E30: ='КВ 1'!E70 -> 0 | F30: ='КВ 1'!F70 -> Детали (покупное изделие) | G30: ='КВ 1'!G70 -> Делатель два | H30: ='КВ 1'!H70 -> 0 | I30: ='КВ 1'!I70 -> 0
B31: ='КВ 1'!B71 -> - | C31: ='КВ 1'!C71 -> Винт DIN 965 M5x16x0.8 A2 | D31: ='КВ 1'!D71 -> 9 | E31: ='КВ 1'!E71 -> 0 | F31: ='КВ 1'!F71 -> Детали (покупное изделие) | G31: ='КВ 1'!G71 -> Делатель раз | H31: ='КВ 1'!H71 -> 0 | I31: ='КВ 1'!I71 -> 0
B32: ='КВ 1'!B72 -> - | C32: ='КВ 1'!C72 -> Винт DIN 965 M5x80x0.8 A2 | D32: ='КВ 1'!D72 -> 4 | E32: ='КВ 1'!E72 -> 0 | F32: ='КВ 1'!F72 -> Детали (покупное изделие) | G32: ='КВ 1'!G72 -> Делатель раз | H32: ='КВ 1'!H72 -> 0 | I32: ='КВ 1'!I72 -> 0

Sheet ПИ 2
E1: 1
B2: Состав изделия | C2: Наименвоание и артикул изделия | D2: Секция инспекционная PZR-VTP-IS-LIS-350-S2-L1240-F2-RAL6029 | F2: Листов 1
A3: № п/п | B3: Обозначение | C3: Наименование | D3: Кол-во на 1 комплект | E3: Кол-во на заказ | F3: Примечание | G3: Производитель | H3: Комменатрии | I3: Ссылки и материалы
B4: =' КВ 2'!B12 -> GG.WP.322.0001.0029 | C4: =' КВ 2'!C12 -> Уголок левый | D4: =' КВ 2'!D12 -> 2 | E4: =' КВ 2'!E12 -> 0 | F4: =' КВ 2'!F12 -> Детали | G4: =' КВ 2'!G12 -> Делатель 3 | H4: =' КВ 2'!H12 -> 0 | I4: =' КВ 2'!I12 -> 0
B5: =' КВ 2'!B13 -> - | C5: =' КВ 2'!C13 -> Гайка для контактной сварки DIN 929-M5-A2 | D5: =' КВ 2'!D13 -> 4 | E5: =' КВ 2'!E13 -> 0 | F5: =' КВ 2'!F13 -> Детали (покупное изделие) | G5: =' КВ 2'!G13 -> Делатель 3 | H5: =' КВ 2'!H13 -> 0 | I5: =' КВ 2'!I13 -> 0
